<?xml version="1.0" encoding="UTF-8"?>
<testng-results total="1" passed="0" failed="1" skipped="0">
  <reporter-output>
  </reporter-output>
  <suite started-at="2022-11-22T02:54:48Z" name="calculatortest.CalculatorTest" finished-at="2022-11-22T02:54:48Z" duration-ms="22">
    <groups>
    </groups>
    <test started-at="2022-11-22T02:54:48Z" name="Command line test" finished-at="2022-11-22T02:54:48Z" duration-ms="22">
      <class name="calculatortest.CalculatorTest">
        <test-method signature="addTest()[pri:0, instance:calculatortest.CalculatorTest@731a74c]" started-at="2022-11-21T20:54:48Z" name="addTest" finished-at="2022-11-21T20:54:48Z" duration-ms="10" status="FAIL">
          <exception class="java.lang.AssertionError">
            <message>
              <![CDATA[expected [22] but found [20]]]>
            </message>
            <full-stacktrace>
              <![CDATA[java.lang.AssertionError: expected [22] but found [20]
	at org.testng.Assert.fail(Assert.java:89)
	at org.testng.Assert.failNotEquals(Assert.java:489)
	at org.testng.Assert.assertEquals(Assert.java:118)
	at org.testng.Assert.assertEquals(Assert.java:365)
	at org.testng.Assert.assertEquals(Assert.java:375)
	at calculatortest.CalculatorTest.addTest(CalculatorTest.java:15)
	at java.base/jdk.internal.reflect.DirectMethodHandleAccessor.invoke(DirectMethodHandleAccessor.java:104)
	at java.base/java.lang.reflect.Method.invoke(Method.java:578)
	at org.testng.internal.MethodInvocationHelper.invokeMethod(MethodInvocationHelper.java:80)
	at org.testng.internal.Invoker.invokeMethod(Invoker.java:715)
	at org.testng.internal.Invoker.invokeTestMethod(Invoker.java:907)
	at org.testng.internal.Invoker.invokeTestMethods(Invoker.java:1237)
	at org.testng.internal.TestMethodWorker.invokeTestMethods(TestMethodWorker.java:127)
	at org.testng.internal.TestMethodWorker.run(TestMethodWorker.java:111)
	at org.testng.TestRunner.privateRun(TestRunner.java:767)
	at org.testng.TestRunner.run(TestRunner.java:617)
	at org.testng.SuiteRunner.runTest(SuiteRunner.java:334)
	at org.testng.SuiteRunner.runSequentially(SuiteRunner.java:329)
	at org.testng.SuiteRunner.privateRun(SuiteRunner.java:291)
	at org.testng.SuiteRunner.run(SuiteRunner.java:240)
	at org.testng.SuiteRunnerWorker.runSuite(SuiteRunnerWorker.java:51)
	at org.testng.SuiteRunnerWorker.run(SuiteRunnerWorker.java:85)
	at org.testng.TestNG.runSuitesSequentially(TestNG.java:1197)
	at org.testng.TestNG.runSuitesLocally(TestNG.java:1122)
	at org.testng.TestNG.run(TestNG.java:1030)
	at org.apache.maven.surefire.testng.TestNGExecutor.run(TestNGExecutor.java:77)
	at org.apache.maven.surefire.testng.TestNGDirectoryTestSuite.execute(TestNGDirectoryTestSuite.java:110)
	at org.apache.maven.surefire.testng.TestNGProvider.invoke(TestNGProvider.java:106)
	at java.base/jdk.internal.reflect.DirectMethodHandleAccessor.invoke(DirectMethodHandleAccessor.java:104)
	at java.base/java.lang.reflect.Method.invoke(Method.java:578)
	at org.apache.maven.surefire.util.ReflectionUtils.invokeMethodWithArray(ReflectionUtils.java:189)
	at org.apache.maven.surefire.booter.ProviderFactory$ProviderProxy.invoke(ProviderFactory.java:165)
	at org.apache.maven.surefire.booter.ProviderFactory.invokeProvider(ProviderFactory.java:85)
	at org.apache.maven.surefire.booter.ForkedBooter.runSuitesInProcess(ForkedBooter.java:115)
	at org.apache.maven.surefire.booter.ForkedBooter.main(ForkedBooter.java:75)
]]>
            </full-stacktrace>
          </exception> <!-- java.lang.AssertionError -->
          <reporter-output>
          </reporter-output>
        </test-method> <!-- addTest -->
      </class> <!-- calculatortest.CalculatorTest -->
    </test> <!-- Command line test -->
  </suite> <!-- calculatortest.CalculatorTest -->
</testng-results>
